Workbook

Sheet Trường hợp kiểm thử
E6: TEST CASE SYSTEM SPRINT 2
E8: Tên dự án | F8: XÂY DỰNG HỆ THÔNG QUẢN LÝ NHÀ XE TÍCH HỢP THANH TOÁN TRỰC TRUYẾN
E9: STT | F9: Chức năng | G9: Sheet Name | H9: Số Testcase
E10: 1 | F10: Tìm kiếm | G10: =HYPERLINK("#'Tìm kiếm'!A1","Tìm kiếm") -> Tìm kiếm | H10: ='Tìm kiếm'!B4 -> 37
E11: 2 | F11: Hiển thị KQ tìm kiếm | G11: =HYPERLINK("#'Hiển thị KQ tìm kiếm'!A1","Hiển thị KQ tìm kiếm") -> Hiển thị KQ tìm kiếm | H11: ='Hiển thị KQ tìm kiếm'!B4 -> 50
E12: 3 | F12: Chi tiết chuyến xe và đặt vé | G12: =HYPERLINK("#'Chi tiết chuyến xe và đặt vé'!A1","Chi tiết chuyến xe và đặt vé") -> Chi tiết chuyến xe và đặt vé | H12: ='Chi tiết chuyến xe và đặt vé'!B4 -> 94
E13: 4 | F13: Chuyến xe của tôi | G13: =HYPERLINK("#'Chuyến xe của tôi'!A1","Chuyến xe của tôi") -> Chuyến xe của tôi | H13: ='Chuyến xe của tôi'!B4 -> 40
E14: 5 | F14: Quản lý xe | G14: =HYPERLINK("#'Quản lý xe'!A1","Quản lý xe") -> Quản lý xe | H14: ='Quản lý xe'!B4 -> 70
E15: 6 | F15: Quản lý chuyến đi | G15: =HYPERLINK("#'Quản lý chuyến đi","Quản lý chuyến đi") -> Quản lý chuyến đi | H15: ='Quản lý chuyến đi'!B4 -> 121
E16: Tổng số testcase của sprint 2 | H16: =H10+H11+H12+H13+H14+H15 -> 412

Sheet Tìm kiếm
A1: Project Name | B1: XÂY DỰNG HỆ THÔNG QUẢN LÝ NHÀ XE TÍCH HỢP THANH TOÁN TRỰC TRUYẾN
A2: Module Code | B2: Tìm kiếm
B3: Tổng số testcase | C3: Hoàn Thành | D3: Lỗi | E3: Bị chặn | F3: Tổng lần kiểm tra
A4: Round 1 | B4: =COUNTIF(A:A,"TC*") -> 37 | C4: =COUNTIF(G:G,"pass") -> 33 | D4: =COUNTIF(G:G,"failed") -> 4 | E4: =COUNTIF(G:G,"Block") -> 0
G22: Round 1
A23: Test Case ID | B23: Sumary | C23: Pre-condition | D23: Test Data | E23: Steps | F23: Expected Result | G23: Result | H23: Test Date | I23: Tester
A24: GUI
A25: TC01 | B25: Xác nhận Upperbar hiển thị menu các chức năng | C25: Người dùng truy cập vào Website của nhà xe | D25: N/ A | E25: Quan sát Upperbar bên phải | F25: Hiển thị Trang chủ, Tuyến phổ biến, Liên hệ, avatar Login, role "Trang chủ" | G25: pass | H25: 17/09/2025 | I25: Ly
A26: TC02 | B26: Xác nhận hiển thị đúng Avatar khi khách hàng chưa login | C26: Người dùng truy cập vào Website của nhà xe | D26: N/ A | E26: quan sát Avatar ở bên góc phải của thanh ngang trên | F26: Hiển thị avatar mặc định (icon người dùng + placeholder "LOGIN) tại góc phải trên | G26: pass | H26: 17/09/2025 | I26: Ly
A27: TC03 | B27: Xác nhận hiển thị đúng Avatar khi khách hàng đã login | C27: Người dùng truy cập vào Website của nhà xe | D27: N/ A | E27: quan sát Avatar ở bên góc phải của thanh ngang trên | F27: Hiển thị đúng avatar cá nhân | G27: pass | H27: 17/09/2025 | I27: Ly
A28: TC04 | B28: Xác nhận Box tìm kiếm + Banner hiển thị đúng | C28: Người dùng truy cập vào Website của nhà xe | D28: N/ A | E28: Quan sát box Tìm kiếm + Banner ở đầu trang | F28: Banner nằm dưới box Tìm kiếm, Box tìm kiếm hiển thi đầy đủ các trường (Địa điểm đớn, Địa điểm trả khách, Nút chuyển đổi vị trí, chọn xe đưa đón chung/ riêng, Ngày khởi hành, khứ hồi, ngày về, số hành khách, Button Tìm kiếm) | G28: pass | H28: 17/09/2025 | I28: Ly
A29: TC05 | B29: Xác nhận Tuyến phổ biến hiển thị danh sách tuyến đường | C29: Danh sách tuyến đường có dữ liệu trong hệ thống | D29: N/ A | E29: Quan sát danh sách tuyến đường ở khu vực tuyến phổ biên | F29: Hiển thị danh sách các tuyến đường đi qua, số km, số giờ, giá tiền | G29: pass | H29: 17/09/2025 | I29: Ly
A30: TC06 | B30: Xác nhận Footer hiển thị đầy đủ thông tin | C30: Người dùng truy cập vào Website của nhà xe | D30: N/ A | E30: Quan sát nội dung ở cuối trang | F30: Footer hiển thị đầy đủ thông tin của nhà xe bao gồm (Slogan của nhà xe, số hotline, email, thời gian hỗ trợ tư vấn, một số thông tin về nhà xe...) | G30: pass | H30: 17/09/2025 | I30: Ly
A31: FUNCTION
A32: TC07 | B32: Xác nhận tìm kiếm thành công khi người dùng nhập đầy đủ thông tin | C32: Người dùng truy cập trang chủ | D32: Địa điểm đón: TP Đà Nẵng, Địa điểm trả: Tp Hồ Chí Minh, Xe đưa đón: Tick chọn 1 trong2 check box Ngày khởi hành: 18/9/2025 Số hành khách: 1 | E32: 1, Nhập đầy đủ thông tin 2. Click vào checkbox xe đưa đón 3. Nhấp "Tìm kiếm" | F32: Tìm kiếm thành công và chuyển sang trang hiển thị kết quả tìm kiếm | G32: pass | H32: 17/09/2025 | I32: Ly
A33: TC08 | B33: Xác nhận tìm kiếm thành công khi người dùng không chọn xe đưa đón | C33: Người dùng truy cập trang chủ | D33: Địa điểm đón: TP Đà Nẵng, Địa điểm trả: Tp Hồ Chí Minh, Xe đưa đón: Ngày khởi hành: 18/9/2025 Số hành khách: 1 | E33: 1. Nhập đúng các trường có trong box 2. Không tick chọn xe đưa đón 3. Bấm "Tìm kiếm" | F33: Tìm kiếm thành công và chuyển sang trang hiển thị kết quả tìm kiếm | G33: pass | H33: 17/09/2025 | I33: Ly
A34: TC09 | B34: Xác nhận tìm kiếm thành công khi người dùng không chọn số hành khách vẫn cho phép tìm kiếm | C34: Người dùng truy cập trang chủ | D34: Địa điểm đón: TP Đà Nẵng, Địa điểm trả: Tp Hồ Chí Minh, Xe đưa đón: chung Ngày khởi hành: 18/9/2025 Số hành khách: | E34: 1. Nhập đúng các trường có trong box 2. Không chọn số hành khách 3. Bấm "Tìm kiếm" | F34: Tìm kiếm thành công và chuyển sang trang hiển thị kết quả tìm kiếm | G34: pass | H34: 17/09/2025 | I34: Ly
A35: TC10 | B35: Kiểm tra click menu Trang chủ | C35: Người dùng đang truy cập trang chủ | D35: N/ A | E35: 1. Nhấp vào "Trang chủ" | F35: Hệ thống load lại trang chủ | G35: pass | H35: 17/09/2025 | I35: Ly
A36: TC11 | B36: Kiểm tra click menu Tuyến phổ biến | C36: Người dùng đang truy cập trang chủ | D36: N/ A | E36: 1. Nhấp vào "Tuyến phổ biến" | F36: Hệ thống chuyển xuống tuyến phổ biến | G36: pass | H36: 17/09/2025 | I36: Ly
A37: TC12 | B37: Kiểm tra click menu Liên hệ | C37: Người dùng đang truy cập trang chủ | D37: N/ A | E37: 1. Nhấp vào "Liên hệ" | F37: Hệ thống chuyển sang trang liên hệ | G37: pass | H37: 17/09/2025 | I37: Ly
A38: TC13 | B38: Kiểm tra click menu Login | C38: Người dùng đang truy cập trang chủ | D38: N/ A | E38: 1. Nhấp vào "Login" | F38: Người dùng bấm vào để Login, khi đã login avatar chuyển qua trang thái đã đăng nhập | G38: pass | H38: 17/09/2025 | I38: Ly
A39: TC14 | B39: Kiểm tra trạng thái nút "Login" khi người dùng chưa đăng nhập | C39: Người dùng chưa đang nhập | D39: N/ A | E39: 1. Nhấp vào "Login" | F39: Nút hiển thị đúng chữ "Login", khi nhấp vào hệ thống chuyển sang trang đăng nhập | G39: pass | H39: 17/09/2025 | I39: Ly
A40: TC15 | B40: Kiểm tra trạng thái nút "Login" khi người dùng đã đăng nhập | C40: Người dùng đã đăng nhập | D40: N/ A | E40: 1. Nhấp vào avatar | F40: Khi nhấp vào avatar, hiển thị link các trang (thông tin tài khoản, chuyến xe của tôi, đánh giá của tôi) và Đăng xuất | G40: pass | H40: 17/09/2025 | I40: Ly
A41: TC16 | B41: Xác nhận hiển thị đúng khi nhấp vào "Thông tin tài khoản" | C41: Người dùng đã đăng nhập | D41: N/ A | E41: 1. Nhấp vào avatar 2. Nhấp "Thông tin tài khoản" | F41: Hệ thống chuyển sang trang thông tin tài khoản | G41: pass | H41: 17/09/2025 | I41: Ly
A42: TC17 | B42: Xác nhận hiển thị đúng khi nhấp vào "Chuyến xe của tôi" | C42: Người dùng đã đăng nhập | D42: N/ A | E42: 1. Nhấp vào avatar 2. Nhấp "Chuyến xe của tôi | F42: Hệ thống chuyển sang trang chuyến xe của tôi | G42: pass | H42: 17/09/2025 | I42: Ly
A43: TC18 | B43: Xác nhận hiển thị đúng khi nhấp vào "Đánh giá của tôi" | C43: Người dùng đã đăng nhập | D43: N/ A | E43: 1. Nhấp vào avatar 2. Nhấp "Đánh giá của tôi" | F43: Hệ thống chuyển sang trang đánh giá của tôi | G43: pass | H43: 17/09/2025 | I43: Ly
... A62: TC37 | B62: Xác nhận hiển thị đúng khi nhấp vào danh sách các tuyến | C62: Người dùng đã đăng nhập vào hệ thống | D62: Chọn tuyến đường mà người dùng muốn đi | E62: 1. Bấm vào tuyến đường mong muốn | F62: Chuyển đến trang hiển thị kết quả tìm kiếm | G62: pass | H62: 17/09/2025 | I62: Ly

Sheet Hiển thị KQ tìm kiếm
A1: Project Name | B1: XÂY DỰNG HỆ THÔNG QUẢN LÝ NHÀ XE TÍCH HỢP THANH TOÁN TRỰC TRUYẾN
A2: Module Code | B2: Hiển thị KQ tìm kiếm
B3: Tổng số testcase | C3: Hoàn Thành | D3: Lỗi | E3: Bị chặn | F3: Tổng lần kiểm tra
A4: Round 1 | B4: =COUNTIF(A:A,"TK*") -> 50 | C4: =COUNTIF(G:G,"pass") -> 46 | D4: =COUNTIF(G:G,"failed") -> 4 | E4: =COUNTIF(G:G,"Block") -> 0
C19: ,
G22: Round 1
A23: Test Case ID | B23: Sumary | C23: Pre-condition | D23: Test Data | E23: Steps | F23: Expected Result | G23: Result | H23: Test Date | I23: Tester
A24: GUI
A25: HIỂN THỊ KẾT QUẢ TÌM KIẾM
A26: TK01 | B26: Kiểm tra hiển thị đầy đủ các trường trong box tìm kiếm | C26: Truy cập trang Hiển thị kết quả tìm kiếm | D26: N/ A | E26: 1. Truy cập trang Hiển thị kết quả tìm kiếm 2.Quan sát khu vực tìm kiếm | F26: Hiển thị đầy đủ: Điểm đón, điểm trả, ngày khởi hành, ngày về, nút tìm kiếm | G26: pass | H26: 17/09/2025 | I26: Thi
A27: TK02 | B27: Kiểm tra sidebar sắp xếp hiển thị đầy đủ các trường | C27: Truy cập trang Hiển thị kết quả tìm kiếm | D27: N/ A | E27: 1. Truy cập trang Hiển thị kết quả tìm kiếm 2.Quan sát sidebar sắp xếp | F27: Các tiêu chí sắp xếp hiển thị: Giờ sớm nhất, muộn nhất, giá, đánh giá | G27: pass | H27: 17/09/2025 | I27: Thi
A28: TK03 | B28: Kiểm tra sidebar bộ lọc hiển thị đầy đủ các trường | C28: Truy cập trang Hiển thị kết quả tìm kiếm | D28: N/ A | E28: 1. Truy cập trang Hiển thị kết quả tìm kiếm 2.Quan sát sidebar bộ lọc | F28: Các bộ lọc: Giờ đi, giá vé, điểm đón, trả, nhà xe, vị trí, loại xe hiển thị đầy đủ | G28: pass | H28: 17/09/2025 | I28: Thi
A29: TK04 | B29: Kiểm tra radio button “Sắp xếp” | C29: Truy cập trang Hiển thị kết quả tìm kiếm | D29: N/ A | E29: Click từng radio button | F29: Chỉ 1 radio được chọn, các nút khác bỏ chọn | G29: pass | H29: 17/09/2025 | I29: Thi
A30: TK05 | B30: Kiểm tra hiển thị bộ lọc | C30: Truy cập trang Hiển thị kết quả tìm kiếm | D30: N/ A | E30: Mở bộ lọc | F30: Hiển thị đủ: Giá vé, điểm đón, điểm trả, nhà xe, vị trí ngồi, loại xe | G30: pass | H30: 17/09/2025 | I30: Thi
A31: TK06 | B31: Kiểm tra mở dropdown | C31: Có bộ lọc | D31: N/ A | E31: Click mở dropdown | F31: Danh sách tùy chọn hiển thị đúng | G31: pass | H31: 17/09/2025 | I31: Thi
A32: TK07 | B32: Kiểm tra đóng dropdown | C32: Dropdown đang mở | D32: N/ A | E32: Click lại dropdown | F32: Dropdown đóng lại | G32: pass | H32: 17/09/2025 | I32: Thi
A33: TK08 | B33: Kiểm tra nút xóa bộ lọc | C33: Đã chọn lọc | D33: N/ A | E33: Click nút xóa bộ lọc | F33: Các bộ lọc bị xóa, hiển thị màu xanh | G33: pass | H33: 17/09/2025 | I33: Thi
A34: TK09 | B34: Hiển thị thông tin chuyến xe | C34: Có kết quả tìm kiếm | D34: N/ A | E34: Quan sát từng chuyến xe | F34: Hiển thị: Hình ảnh, giá, giờ đi/đến, điểm đón/trả, link chi tiết, nút chọn, số chỗ | G34: pass | H34: 17/09/2025 | I34: Thi
A35: TK10 | B35: Link “Thông tin chi tiết” hoạt động | C35: Có kết quả | D35: N/ A | E35: Click link chi tiết | F35: Mở trang thông tin chi tiết chuyến xe | G35: pass | H35: 17/09/2025 | I35: Thi
A36: TK11 | B36: Nút “Chọn chuyến” hoạt động | C36: Có kết quả | D36: N/ A | E36: Click “Chọn chuyến” | F36: Chuyển đến trang thanh toán | G36: pass | H36: 17/09/2025 | I36: Thi
A37: FUNCTION
A38: TK12 | B38: Xác nhận hệ thống đồng bộ chính xác thông tin người dùng nhập hoặc chọn giữa các bước trong quy trình đặt vé | C38: Người dùng đã tìm kiếm ở trang chủ | D38: Điểm đón: Hà Nội, Điểm trả: Hải Phòng, Ngày khởi hành: 25/09/2025 | E38: 1. Tại trang chủ, nhập thông tin vào box tìm kiếm 2. Nhấn “Tìm kiếm” 3. Quan sát box tìm kiếm ở trang kết quả | F38: Thông tin người dùng nhập hoặc chọn ở các bước trước được lưu giữ và hiển thị chính xác khi quay lại hoặc chuyển tiếp | G38: pass | H38: 17/09/2025 | I38: Thi
A39: TK13 | B39: Xác nhận tìm kiếm chuyến xe từ trang chủ sang trang kết quả tìm kiếm | C39: Người dùng truy cập trang hiển chị kết quả tìm kiếm | D39: Điểm đón: Hà Nội, Điểm trả: Hải Phòng, Ngày khởi hành: 25/09/2025 | E39: 1. Nhập thông tin tìm kiếm đầy đủ; 2. Click “Tìm kiếm” | F39: Hiển thị kết quả chuyến xe đúng với điểm đón – điểm trả – ngày đã nhập | G39: pass | H39: 17/09/2025 | I39: Thi
A40: TK14 | B40: Xác nhận tìm kiếm thành công khi nhập đầy đủ thông tin | C40: Người dùng truy cập trang hiển chị kết quả tìm kiếm | D40: Điểm đón: Đà Nẵng, Điểm trả: TP.HCM, Ngày khởi hành: 18/09/2025 | E40: 1. Nhập đầy đủ thông tin; 2. Click “Tìm kiếm” | F40: Hiển thị danh sách chuyến đi | G40: pass | H40: 17/09/2025 | I40: Thi
A41: TK15 | B41: Xác nhận tìm kiếm khi thông tin hợp lệ | C41: Người dùng truy cập trang hiển chị kết quả tìm kiếm | D41: Điểm đón: Hà Nội, Điểm trả: Hải Phòng, Ngày khởi hành: 25/09/2025 | E41: 1. Click nút “Chọn chuyến” ở một chuyến xe bất kỳ | F41: Chuyển sang trang chi tiết chuyến đi | G41: pass | H41: 17/09/2025 | I41: Thi
A42: TK16 | B42: Xác nhận hiển thị đúng kết quả tìm kiếm khi chuyển trang | C42: Người dùng đã tìm kiếm ở trang chủ | D42: Điểm đón: Hà Nội, Điểm trả: Hải Phòng, Ngày khởi hành: 25/09/2025 | E42: 1. Tại trang chủ, nhập thông tin vào box tìm kiếm 2. Nhấn “Tìm kiếm” 3. Quan sát box tìm kiếm ở trang kết quả | F42: Tất cả dữ liệu tìm kiếm từ trang chủ được truyền và hiển thị chính xác trên trang kết quả tìm kiếm | G42: pass | H42: 17/09/2025 | I42: Thi
A43: TK17 | B43: Xác nhận hiển thị đúng khi người dùng tìm kiếm chuyến xe mới | C43: Người dùng truy cập trang hiển chị kết quả tìm kiếm | D43: Điểm đón: Quảng nam, Điểm trả: Gia Lai, Ngày khởi hành: 25/09/2025 | E43: 1. Nhập điểm đón, điểm trả, ngày khởi hành 2. Nhấp "Tìm kiếm" | F43: Hệ thống hiển thị danh sách chuyến đúng theo dữ liệu mới nhập, box tìm kiếm hiển thị thông tin mới | G43: pass | H43: 17/09/2025 | I43: Thi
A44: TK18 | B44: Xác nhận hiển thị đúng khi người dùng tìm kiếm chuyến xe trùng với lần tìm kiếm trước | C44: Người dùng truy cập trang hiển chị kết quả tìm kiếm | D44: Điểm đón: Hà Nội, Điểm trả: Hải Phòng, Ngày khởi hành: 25/09/2025 | E44: 1. Nhập điểm đón, điểm trả, ngày khởi hành đã tìm kiếm trước đó 2. Nhấp "Tìm kiếm" | F44: Kết quả hiển thị không đổi, nhưng hệ thống vẫn reload kết quả để đảm bảo tính đồng bộ | G44: pass | H44: 17/09/2025 | I44: Thi
A45: TK19 | B45: Hiển thị lỗi khi bỏ trống trường địa điểm đón | C45: Người dùng truy cập trang hiển chị kết quả tìm kiếm | D45: Điểm đón: Điểm trả: Hải Phòng, Ngày khởi hành: 25/09/2025 | E45: 1. Bỏ trống điểm đón; 2. Nhập các thông tin còn lại; 3. Click “Tìm kiếm” | F45: Hiển thị thông báo: “Vui lòng nhập địa điểm đón” | G45: pass | H45: 17/09/2025 | I45: Thi
A46: TK20 | B46: Hiển thị lỗi khi địa điểm đón không có trong tuyến đường | C46: Người dùng truy cập trang hiển chị kết quả tìm kiếm | D46: Điểm đón: Campuchia, Điểm trả: Hải Phòng, Ngày khởi hành: 25/09/2025 | E46: 1. Nhập địa điểm đón không nằm trong hệ thống tuyến; 2. Click “Tìm kiếm” | F46: Thông báo: “Địa điểm tìm kiếm không có trong tuyến đường” | G46: pass | H46: 17/09/2025 | I46: Thi
A47: TK21 | B47: Hiển thị lỗi khi bỏ trống trường địa điểm trả | C47: Người dùng truy cập trang hiển chị kết quả tìm kiếm | D47: Điểm đón: Hà Nội, Điểm trả: Ngày khởi hành: 25/09/2025 | E47: 1. Nhập điểm đón; 2. Bỏ trống điểm trả; 3. Click “Tìm kiếm” | F47: Thông báo: “Vui lòng nhập địa điểm trả” | G47: pass | H47: 17/09/2025 | I47: Thi
A48: TK22 | B48: Hiển thị lỗi khi địa điểm trả không có trong tuyến đường | C48: Người dùng truy cập trang hiển chị kết quả tìm kiếm | D48: Điểm đón: Hà Nội, Điểm trả: Thái Lan, Ngày khởi hành: 25/09/2025 | E48: 1. Nhập địa điểm trả không hợp lệ; 2. Click “Tìm kiếm” | F48: Thông báo: “Địa điểm tìm kiếm không có trong tuyến đường” | G48: failed | H48: 17/09/2025 | I48: Thi
A49: TK23 | B49: Kiểm tra khi click nút chuyển đổi giữa điểm đón và trả | C49: Người dùng truy cập trang hiển chị kết quả tìm kiếm | D49: Địa điểm đón: Hà Nội, Địa điểm trả: Hải Phòng Ngày khởi hành: 25/09/2025 | E49: 1. Nhập thông tin; 2. Click icon đổi chỗ giữa điểm đón và điểm trả | F49: Hai trường hoán đổi dữ liệu cho nhau | G49: pass | H49: 17/09/2025 | I49: Thi
... A76: TK50 | B76: Xác nhận hiển thị thông tin click vào dropdown "Xóa toàn bộ bộ lọc" | C76: Đã có lọc trước đó | D76: N/ A | E76: 1. Click “Xóa lọc” hoặc “Xóa tất cả”; 2. Quan sát kết quả | F76: Danh sách chuyến xe quay về trạng thái mặc định (không lọc) | G76: pass | H76: 17/09/2025 | I76: Thi

Sheet Chi tiết chuyến xe và đặt vé
A1: Project Name | B1: XÂY DỰNG HỆ THÔNG QUẢN LÝ NHÀ XE TÍCH HỢP THANH TOÁN TRỰC TRUYẾN
A2: Module Code | B2: Chi tiết chuyến xe và đặt vé
B3: Tổng số testcase | C3: Hoàn Thành | D3: Lỗi | E3: Bị chặn | F3: Tổng lần kiểm tra
A4: Round 1 | B4: =COUNTIF(A:A,"CD*") -> 94 | C4: =COUNTIF(G:G,"pass") -> 91 | D4: =COUNTIF(G:G,"failed") -> 3 | E4: =COUNTIF(G:G,"Block") -> 0
G22: Round 1
A23: Test Case ID | B23: Sumary | C23: Pre-condition | D23: Test Data | E23: Steps | F23: Expected Result | G23: Result | H23: Test Date | I23: Tester
A24: GUI
A25: CHI TIẾT CHUYẾN ĐI
A26: CD01 | B26: Xác nhận hiển thị đúng breadcrumb | C26: Người dùng truy cập trang Chi tiết Chuyến đi | D26: N/ A | E26: Quan sát breadcrumb | F26: Hiển thị đúng "Quay lại > Chi tiết Chuyến Đi", font chữ rõ ràng, không lỗi ký tự | G26: pass | H26: 17/09/2025 | I26: Thi
A27: CD02 | B27: Xác nhận box tìm kiếm hiển thị đủ trường | C27: Người dùng truy cập trang chủ | D27: N/ A | E27: Quan sát box tìm kiếm | F27: Hiển thị đủ các trường (Điểm đi, Điểm đến, Ngày khởi hành, Thêm ngày về) | G27: pass | H27: 17/09/2025 | I27: Thi
A28: CD03 | B28: Xác nhận button "Tìm kiếm" hiển thị đúng | C28: Người dùng truy cập trang chủ | D28: N/ A | E28: Quan sát button Tìm kiếm | F28: Hiển thị màu xanh, đúng kích thước | G28: pass | H28: 17/09/2025 | I28: Thi
A29: CD04 | B29: Xác nhận thông tin chuyến xe hiển thị đúng | C29: Người dùng tìm kiếm chuyến xe | D29: N/ A | E29: Quan sát kết quả hiển thị | F29: Hiển thị tên xe, loại xe, số ghế, giá vé, số ghế trống | G29: pass | H29: 17/09/2025 | I29: Thi
A30: CD05 | B30: Xác nhận ảnh xe hiển thị đầy đủ | C30: Người dùng tìm kiếm chuyến xe | D30: N/ A | E30: Quan sát ảnh xe | F30: Hình ảnh hiển thị đầy đủ, rõ nét, có thumbnail đã chọn | G30: pass | H30: 17/09/2025 | I30: Thi
A31: CD06 | B31: Xác nhận button "Chọn chuyến" hiển thị đúng | C31: Người dùng tìm kiếm chuyến xe | D31: N/ A | E31: Quan sát nút "Chọn chuyến" | F31: Hiển thị màu vàng, chữ rõ, có hiệu ứng khi di chuột vào | G31: pass | H31: 17/09/2025 | I31: Thi
A32: CD07 | B32: Xác nhận tab Đón/Trả hiển thị đúng | C32: Người dùng mở popup chọn chuyến | D32: N/ A | E32: Quan sát tab | F32: Hiển thị lưu chọn, danh sách điểm đón/điểm trả đầy đủ | G32: pass | H32: 17/09/2025 | I32: Thi
A33: CD08 | B33: Xác nhận tab Tiện ích hiển thị đúng | C33: Người dùng vào trang chi tiết chuyến | D33: N/ A | E33: Quan sát tab | F33: Hiển thị đầy đủ thông tin tiện ích: Wifi, nước, điều hòa, rèm cửa, TV LED… | G33: pass | H33: 17/09/2025 | I33: Thi
A34: CD09 | B34: Xác nhận tab Đánh giá hiển thị đúng | C34: Người dùng vào trang chi tiết chuyến | D34: N/ A | E34: Quan sát tab | F34: Hiển thị phần đánh giá của khách hàng | G34: pass | H34: 17/09/2025 | I34: Thi
A35: CD10 | B35: Xác nhận bộ lọc đánh giá hiển thị đúng | C35: Người dùng vào tab đánh giá | D35: N/ A | E35: Chọn filter theo sao | F35: Hiển thị đúng số lượng đánh giá theo filter | G35: pass | H35: 17/09/2025 | I35: Thi
A36: CD11 | B36: Xác nhận hiển thị đúng star rating | C36: Người dùng vào tab đánh giá | D36: N/ A | E36: Quan sát hiển thị sao | F36: Hiển thị 5 sao, có thể lọc các mục (An toàn, thái độ, đúng giờ, chất lượng…) | G36: pass | H36: 17/09/2025 | I36: Thi
A37: POPUP CHỌN CHUYẾN
A38: CD12 | B38: Xác nhận hiển thị popup chọn ghế | C38: Người dùng click "Chọn chuyến" | D38: N/ A | E38: Quan sát popup hiển thị | F38: Popup hiển thị với danh sách ghế, chú thích giá vé | G38: pass | H38: 17/09/2025 | I38: Thi
A39: CD13 | B39: Xác nhận hiển thị đúng chú thích ghế | C39: Người dùng mở popup chọn ghế | D39: N/ A | E39: Quan sát chú thích | F39: Hiển thị 4 trạng thái: Ghế đã hết (xám), Đang chọn (xanh lá), Giường đôi (tím), Giường đơn (vàng) | G39: pass | H39: 17/09/2025 | I39: Thi
A40: CD14 | B40: Xác nhận hiển thị đúng sơ đồ tầng | C40: Người dùng mở popup chọn ghế | D40: N/ A | E40: Quan sát sơ đồ | F40: Ghế hiển thị đủ 2 tầng: Tầng dưới, Tầng trên | G40: pass | H40: 17/09/2025 | I40: Thi
A41: CD15 | B41: Xác nhận button Tiếp tục hiển thị đúng | C41: Người dùng chọn ghế hợp lệ | D41: N/ A | E41: Nhấn "Tiếp tục" | F41: Hiển thị màu xanh, chuyển sang trang thanh toán | G41: pass | H41: 17/09/2025 | I41: Thi
A42: CD16 | B42: Xác nhận link Quay lại hiển thị đúng | C42: Người dùng mở popup chọn ghế | D42: N/ A | E42: Nhấn "Quay lại" | F42: Hiển thị màu xám, quay lại trang chi tiết chuyến đi | G42: pass | H42: 17/09/2025 | I42: Thi
A43: CD17 | B43: Xác nhận hiển thị đúng khi click vào (X) | C43: Người dùng mở popup chọn ghế | D43: N/ A | E43: Nhấn "X" trên góc popup | F43: Thoát popup | G43: pass | H43: 17/09/2025 | I43: Thi
A44: POPUP CHI TIẾT ĐÓN TRẢ
A45: CD18 | B45: Xác nhận hiển thị danh sách điểm đón và điểm trả | C45: Người dùng mở popup chọn điểm đón/trả | D45: N/ A | E45: Quan sát danh sách | F45: Danh sách hiển thị rõ ràng, có radio chọn, sắp xếp mặc định theo giờ sớm nhất | G45: pass | H45: 17/09/2025 | I45: Thi
A46: CD19 | B46: Xác nhận Dropdown sắp xếp hiển thị đúng | C46: Người dùng mở popup chọn điểm đón/trả | D46: N/ A | E46: Thay đổi lựa chọn trong dropdown | F46: Danh sách cập nhật đúng theo lựa chọn (Muộn nhất hoặc Sớm nhất) | G46: pass | H46: 17/09/2025 | I46: Thi
A47: CD20 | B47: Xác nhận ô tìm kiếm điểm đón/trả hiển thị đúng | C47: Người dùng mở popup chọn điểm đón/trả | D47: N/ A | E47: Nhập text vào ô "Tìm trong danh sách" | F47: Hiển thị đúng kết quả theo từ khóa | G47: pass | H47: 17/09/2025 | I47: Thi
A48: CD21 | B48: Xác nhận hiển thị đúng tổng cộng giá vé | C48: Người dùng mở popup chọn điểm đón/trả | D48: N/ A | E48: Quan sát thông tin tổng cộng | F48: Hiển thị đúng tổng cộng giá vé | G48: failed | H48: 17/09/2025 | I48: Thi
A49: CD22 | B49: Xác nhận link Quay lại hiển thị đúng | C49: Người dùng mở popup chọn điểm đón/trả | D49: N/ A | E49: Nhấn "Quay lại" | F49: Quay lại popup chọn ghế | G49: pass | H49: 17/09/2025 | I49: Thi
A50: CD23 | B50: Xác nhận button Tiếp tục hiển thị đúng | C50: Người dùng đã chọn điểm đón/trả | D50: N/ A | E50: Nhấn "Tiếp tục" | F50: Hiển thị màu xanh, chuyển đến trang thanh toán | G50: pass | H50: 17/09/2025 | I50: Thi
A51: CD24 | B51: Xác nhận hiển thị đúng khi click vào (X) | C51: Người dùng mở popup chọn điểm đón/trả | D51: N/ A | E51: Nhấn "X" | F51: Thoát popup | G51: failed | H51: 17/09/2025 | I51: Thi
A52: FUNCTION
A53: CHI TIẾT CHUYẾN ĐI
A54: CD25 | B54: Xác nhận hệ thống đồng bộ chính xác thông tin người dùng nhập hoặc chọn giữa các bước trong quy trình đặt vé | C54: Người dùng đã tìm kiếm ở trang chủ | D54: Điểm đón: Hà Nội, Điểm trả: Hải Phòng, Ngày khởi hành: 25/09/2025 | E54: 1. Nội dung tìm kiếm từ trang Hiển thị kết quả tìm kiếm 2. Quan sát box tìm kiếm ở trang chi tiết chuyến đi | F54: Thông tin người dùng nhập hoặc chọn ở các bước trước được lưu giữ và hiển thị chính xác khi quay lại hoặc chuyển tiếp | G54: pass | H54: 17/09/2025 | I54: Thi
A55: CD26 | B55: Xác nhận hiển thị đúng tìm kiếm chuyến xe từ trang hiển thị kết quả sang trang chi tiết chuyến đi | C55: Người dùng đã nhập đầy đủ điểm đón, điểm trả, ngày khởi hành hợp lệ | D55: Điểm đón: Hà Nội, Điểm trả: Đà Nẵng, Ngày khởi hành: 22/09/2025 | E55: 1. Nhập thông tin tìm kiếm. 2. Nhấn nút Tìm kiếm. 3. Chọn 1 chuyến xe từ danh sách kết quả. | F55: Hệ thống hiển thị thông tin chi tiết chuyến xe theo đúng điểm đón – điểm trả – ngày khởi hành đã nhập. | G55: failed | H55: 17/09/2025 | I55: Thi
A56: CD27 | B56: Xác nhận tìm kiếm thành công khi người dùng nhập đầy đủ thông tin | C56: Người dùng đã mở box tìm kiếm trên trang chủ | D56: Điểm đón: Hà Nội, Điểm trả: Đà Nẵng, Ngày khởi hành: 22/09/2025 | E56: 1. Nhập điểm đón, điểm trả, ngày khởi hành. 2. Nhấn Tìm kiếm. | F56: Hệ thống hiển thị danh sách chuyến đi hợp lệ khớp với dữ liệu. | G56: pass | H56: 17/09/2025 | I56: Thi
A57: CD28 | B57: Xác nhận hiển thị đúng khi người dùng tìm kiếm chuyến xe hợp lệ | C57: Người dùng đã có kết quả tìm kiếm hiển thị | D57: Điểm đón: Hà Nội, Điểm trả: Đà Nẵng, Ngày khởi hành: 22/09/2025 | E57: 1. Nhấn nút Chọn chuyến trên kết quả tìm kiếm. | F57: Hệ thống chuyển sang trang chi tiết chuyến đi và hiển thị đầy đủ dữ liệu. | G57: pass | H57: 17/09/2025 | I57: Thi
...

Sheet Chuyến xe của tôi
A1: Project Name | B1: XÂY DỰNG HỆ THÔNG QUẢN LÝ NHÀ XE TÍCH HỢP THANH TOÁN TRỰC TRUYẾN
A2: Module Code | B2: Chuyến xe của tôi
B3: Tổng số testcase | C3: Hoàn Thành | D3: Lỗi | E3: Bị chặn | F3: Tổng lần kiểm tra
A4: Round 1 | B4: =COUNTIF(A:A,"CD*") -> 40 | C4: =COUNTIF(G:G,"pass") -> 37 | D4: =COUNTIF(G:G,"failed") -> 2 | E4: =COUNTIF(G:G,"Block") -> 0
G21: Round 1
A22: Test Case ID | B22: Sumary | C22: Pre-condition | D22: Test Data | E22: Steps | F22: Expected Result | G22: Result | H22: Test Date | I22: Tester
A23: GUI
A24: CHUYẾN ĐI CỦA TÔI
A25: CD01 | B25: Xác nhận hiển thị tiêu đề “Chuyến Xe Của Tôi” | C25: Truy cập trang chuyến đi của tôi | D25: N/A | E25: 1. Đăng nhập vào hệ thống 2. Trên thanh menu, chọn Chuyến Xe Của Tô | F25: Trang hiển thị tiêu đề Chuyến Xe Của Tôi ở đầu trang | G25: pass | H25: 17/09/2025 | I25: Yên
A26: CD02 | B26: Xác nhận hiển thị có 3 tab: Hiện Tại, Đã Đi, Đã Hủy | C26: Truy cập trang chuyến đi của tôi | D26: N/A | E26: 1. Truy cập menu Chuyến Xe Của Tôi 2. Quan sát phần hiển thị các tab | F26: Hiển thị đủ 3 tab: Hiện Tại, Đã Đi, Đã Hủy | G26: pass | H26: 17/09/2025 | I26: Yên
A27: CD03 | B27: Xác nhận hiển thị danh sách chuyến xe hiển thị đầy đủ thông tin | C27: Truy cập trang chuyến đi của tôi | D27: N/A | E27: 1. Vào tab Hiện Tại 2. Quan sát thông tin hiển thị trên chuyến xe | F27: Hiển thị: ảnh xe, giờ đi, điểm đón, điểm đến, trạng thái (Đã đặt), tổng số tiền, nút Thông tin chi tiết, nút Hủy | G27: pass | H27: 17/09/2025 | I27: Yên
A28: CD04 | B28: Xác nhận hiển thị popup hủy vé hiển thị đúng giao diện | C28: Truy cập trang chuyến đi của tôi | D28: N/A | E28: 1. Vào tab Hiện Tại 2. Click nút Hủy trên chuyến xe | F28: Hiển thị popup “Bạn muốn hủy vé?” với 5 checkbox lý do, nút Hủy vé, nút Đóng | G28: pass | H28: 17/09/2025 | I28: Yên
A29: CD05 | B29: Xác nhận hiển thị popup Thông tin chi tiết hiển thị đúng giao diện | C29: Truy cập trang chuyến đi của tôi | D29: N/A | E29: 1. Vào tab Đã đi 2. Click Thông tin chi tiế | F29: Hiển thị popup chi tiết chuyến xe: ảnh, giờ đi, điểm đi/đến, trạng thái đã đặt, thông tin giá tiền | G29: pass | H29: 17/09/2025 | I29: Yên
A30: POPUP HỦY
A31: CD06 | B31: Xác nhận hiển thị lý do hủy vé | C31: Truy cập trang chuyến đi của tôi | D31: N/A | E31: 1. Vào tab Hiện Tại 2. Click nút Hủy trên chuyến xe | F31: Hiển thị popup “Bạn muốn hủy vé?” với 5 checkbox lý do, nút Hủy vé, nút Đóng | G31: pass | H31: 17/09/2025 | I31: Yên
A32: CD07 | B32: Xác nhận hiển thị nút hủy vé | C32: Truy cập trang chuyến đi của tôi | D32: N/A | E32: 1. Vào tab Hiện Tại 2. Click nút Hủy trên chuyến xe | F32: Hiển thị nút hủy vé thành công khi chọn 1 trong 5 lý do | G32: pass | H32: 17/09/2025 | I32: Yên
A33: CD08 | B33: Xác nhận hiển thị nút đóng | C33: Truy cập trang chuyến đi của tôi | D33: N/A | E33: 1. Vào tab Hiện Tại 2. Click nút Hủy trên chuyến xe 3. Click nút đóng | F33: Đóng popup không lưu dữ liệu | G33: pass | H33: 17/09/2025 | I33: Yên
A34: POPUP THÔNG TIN CHI TIẾT
A35: CD09 | B35: Kiểm tra hiển thị popup khi xem chi tiết vé | C35: Người dùng đã chọn vé từ danh sách booking | D35: N/A | E35: 1. Chọn vé trong danh sách 2. Nhấn “Xem chi tiết” | F35: Popup “Chi tiết thông tin chuyến đi” hiển thị đầy đủ thông tin: Tuyến, Nhà xe, Chuyến, Loại xe, Số lượng, Mã ghế, Tạm tính, Mã vé, Giá vé, Bảo hiểm, Điểm đón, Điểm trả | G35: pass | H35: 17/09/2025 | I35: Yên
A36: CD10 | B36: Kiểm tra nút “Đóng” hoạt động | C36: Popup đã hiển thị | D36: N/A | E36: 1. Mở popup 2. Nhấn nút “Đóng” | F36: Popup đóng lại, quay về màn hình trước đó | G36: pass | H36: 17/09/2025 | I36: Yên
A37: CD11 | B37: Kiểm tra tính chính xác của thông tin giá vé | C37: Có vé đã đặt thành công | D37: N/A | E37: 1. Mở popup 2. Xem mục “Tạm tính” và “Giá vé” | F37: “Tạm tính = Giá vé + Bảo hiểm” (920.000đ). Giá vé và bảo hiểm hiển thị đúng | G37: pass | H37: 17/09/2025 | I37: Yên
A38: CD12 | B38: Kiểm tra hiển thị điểm đón/trả và thời gian dự kiến | C38: Chuyến xe có điểm đón/trả | D38: N/A | E38: 1. Mở popup 2. Kiểm tra mục “Điểm đón” và “Điểm trả” | F38: Thông tin địa chỉ hiển thị chính xác, thời gian dự kiến hiển thị đúng định dạng (HH:mm dd/MM/yyyy) | G38: pass | H38: 17/09/2025 | I38: Yên
A39: CD13 | B39: Kiểm tra hiển thị mã vé và mã ghế/giường | C39: Vé có mã vé và ghế đã đặt | D39: N/A | E39: 1. Mở popup 2. Xem mục “Mã vé” và “Mã ghế/giường” | F39: Mã vé và mã ghế hiển thị đúng theo dữ liệu đặt vé | G39: pass | H39: 17/09/2025 | I39: Yên
A40: CD14 | B40: Kiểm tra định dạng tiền tệ hiển thị | C40: Có giá vé và bảo hiểm | D40: N/A | E40: 1. Mở popup 2. Xem các trường giá tiền | F40: Các giá trị hiển thị đúng định dạng: ###.###đ | G40: pass | H40: 17/09/2025 | I40: Yên
A41: CD15 | B41: Kiểm tra hiển thị loại xe | C41: Vé thuộc loại xe cụ thể | D41: N/A | E41: 1. Mở popup 2. Xem mục “Loại xe” | F41: Loại xe hiển thị chính xác theo dữ liệu đặt vé | G41: pass | H41: 17/09/2025 | I41: Yên
A42: CD16 | B42: Kiểm tra trường hợp không có dữ liệu | C42: Người dùng chọn vé đã bị hủy | D42: N/A | E42: 1. Chọn vé đã hủy 2. Nhấn “Xem chi tiết” | F42: Hệ thống báo “Không tìm thấy thông tin vé” hoặc popup hiển thị thông báo lỗi | G42: pass | H42: 17/09/2025 | I42: Yên
A43: FUNCTION
A44: CHUYẾN ĐI CỦA TÔI
A45: CD17 | B45: Xác nhận thông báo hiển thị khi danh sách chuyến xe trống | C45: Truy cập trang chuyến đi của tôi | D45: N/A | E45: 1. Đăng nhập hệ thống bằng tài khoản 2. Vào menu Chuyến Xe Của Tôi 3. Chọn tab Hiện Tại | F45: Hiển thị thông báo “Bạn chưa có chuyến nào” | G45: pass | H45: 17/09/2025 | I45: Yên
A46: CD18 | B46: Xác nhận thông báo hiển thị đúng thông tin với tab đang mở | C46: Truy cập trang chuyến đi của tôi | D46: N/A | E46: 1. Đăng nhập hệ thống bằng tài khoản 2. Vào menu Chuyến Xe Của Tôi 3. Chọn tab Hiện Tại | F46: Hiển thị đúng danh sách đã đặt vé | G46: pass | H46: 17/09/2025 | I46: Yên
A47: CD19 | B47: Xác nhận thông báo hiển thị khi tab Đã đi trống | C47: Truy cập trang chuyến đi của tôi | D47: N/A | E47: 1. Đăng nhập hệ thống bằng tài khoản 2. Vào menu Chuyến Xe Của Tôi 3. Chọn tab đã đi | F47: Hiển thị thông báo “Bạn chưa từng đi chuyến nào” | G47: pass | H47: 17/09/2025 | I47: Yên
A48: CD20 | B48: Xác nhận thông báo hiển thị khi tab Đã hủy trống | C48: Truy cập trang chuyến đi của tôi | D48: N/A | E48: 1. Đăng nhập hệ thống bằng tài khoản 2. Vào menu Chuyến Xe Của Tôi 3. Chọn tab đã hủy | F48: Hiển thị thông báo “Bạn chưa từng hủy chuyến nào” | G48: pass | H48: 17/09/2025 | I48: Yên
A49: CD21 | B49: Xác nhận nút Đóng trong popup chi tiết hoạt động đúng | C49: Truy cập trang chuyến đi của tôi | D49: N/A | E49: 1. Vào tab Đã Đi 2. Click Thông tin chi tiết 3. Click Đóng | F49: Popup đóng lại, vẫn ở tab Đã Đi | G49: failed | H49: 17/09/2025 | I49: Yên
A50: CD22 | B50: Xác nhận hệ thống hiển thị chuyến xe theo đúng ngày giờ đặt | C50: Chuyến xe: Limousine 24 phòng đôi | D50: Chuyến 1: 20/09/2025 Chuyến 2:21/09/2025 | E50: 1. Vào menu Chuyến Xe Của Tôi 2. Chọn tab Hiện Tại 3. Quan sát danh sách | F50: Hiển thị thông báo danh sách được sắp xếp theo thời gian đi | H50: 17/09/2025 | I50: Yên
A51: CD23 | B51: Xác nhận thông báo hiển thị trạng thái chuyến xe hiển thị chính xác sau khi hủy | C51: Ngày đi: 20/09/2025 | D51: Chuyến xe: Limousine 24 phòng đôi Ngày đi: 20/09/2025 giờ đi : 5:00 văn phòng quận 5 - 11:00 văn phòng nha trang tổng số tiền : 900,000Đ Lý do hủy: Đổi kế hoạch | E51: 1. Vào tab Hiện Tại 2. Click Hủy 3. Chọn lý do “Đổi kế hoạch” 4. Click Hủy vé 5. Chuyển sang tab Đã Hủy | F51: Hiển thị thông báo chuyến xe Đã Hủy, trạng thái = “Đã Hủy” | G51: pass | H51: 17/09/2025 | I51: Yên
A52: POPUP HỦY
A53: CD24 | B53: Xác nhận hiển thị chuyến hiện tại, đã đi và hủy thành công chuyến khi người dùng điền đầy đủ thông tin trong popup hủy | C53: Truy cập trang chuyến đi của tôi | D53: Chuyến xe: Limousine chỗ Ngày đi: 25/09/2025 Giá: 500,000đ | E53: 1. Mở popup hủy vé 2. Chọn lý do :“Đặt nhầm chuyến " 3. Click Xác nhận hủy 4. Chuyển sang Trang chủ | F53: Popup hủy vé hiển thị với đầy đủ thông tin chuyến xe và lựa chọn lý do chuyển sang tab trang chủ | G53: pass | H53: 17/09/2025 | I53: Yên
A54: CD25 | B54: Xác nhận hiển thị lỗi trong khi chuyến đang khởi hành | C54: Truy cập trang chuyến đi của tôi | D54: Chuyến xe: Limousine chỗ Ngày đi: 25/09/2025 Giá: 500,000đ | E54: 1. Mở popup hủy vé 2. Chọn lý do :“Đặt nhầm chuyến " 3. Click Xác nhận hủy | F54: Hiển thị thông báo lỗi “chuyến đã khởi hành không thể hủy vé” | G54: pass | H54: 17/09/2025 | I54: Yên
A55: CD26 | B55: Xác nhận hiển thị popup hủy vé khi click nút “Hủy” | C55: Truy cập trang chuyến đi của tôi | D55: Chuyến xe: Limousine chỗ Ngày đi: 25/09/2025 Giá: 500,000đ | E55: 1. Mở popup hủy vé 2. Chọn lý do :“Đặt nhầm chuyến " 3. Click Xác nhận hủy 4. Chuyển sang tab Đã Hủy | F55: Popup hủy vé hiển thị với đầy đủ thông tin chuyến xe và lựa chọn lý do | G55: pass | H55: 17/09/2025 | I55: Yên
A56: CD27 | B56: Xác nhận hiển thị lỗi giới hạn số lần click nút " Hủy" | C56: Truy cập trang chuyến đi của tôi | D56: Chuyến xe: Limousine chỗ Ngày đi: 25/09/2025 Giá: 500,000đ | E56: 1. Mở popup hủy vé 2. Chọn lý do :“Đặt nhầm chuyến " 3. Click Xác nhận hủy ( 5 lần ) | F56: Hệ thống hiển thị thông báo giới hạn “ thử lại sau X phút” | G56: failed | H56: 17/09/2025 | I56: Yên
...

Sheet Quản lý xe
A1: Project Name | B1: XÂY DỰNG HỆ THÔNG QUẢN LÝ NHÀ XE TÍCH HỢP THANH TOÁN TRỰC TRUYẾN
A2: Module Code | B2: Chuyến đi của tôi
B3: Tổng số testcase | C3: Hoàn Thành | D3: Lỗi | E3: Bị chặn | F3: Tổng lần kiểm tra
A4: Round 1 | B4: =COUNTIF(A:A,"QLX*") -> 70 | C4: =COUNTIF(G:G,"pass") -> 70 | D4: =COUNTIF(G:G,"failed") -> 0 | E4: =COUNTIF(G:G,"Block") -> 0
G22: Round 1
A23: Test Case ID | B23: Sumary | C23: Pre-condition | D23: Test Data | E23: Steps | F23: Expected Result | G23: Result | H23: Test Date | I23: Tester
A24: GUI
A25: QLX01 | B25: Kiểm tra hiển thị tiêu đề “DANH SÁCH XE” | C25: Người quản lý đã đăng nhập | D25: N/A | E25: Vào menu Quản lý xe | F25: Tiêu đề “DANH SÁCH XE” hiển thị rõ ràng, đúng font, căn chỉnh chuẩn | G25: pass | H25: 17/09/2025 | I25: Vy
A26: QLX02 | B26: Kiểm tra cột tiêu đề bảng | C26: Người quản lý đã đăng nhập | D26: N/A | E26: Quan sát bảng danh sách xe | F26: Hiển thị đầy đủ các cột: ID Xe, Loại Xe, Biển số xe, Số Ghế, Tuyến đường, Trạng Thái, Note, Dịch Vụ | G26: pass | H26: 17/09/2025 | I26: Vy
A27: QLX03 | B27: Kiểm tra nút Thêm hiển thị | C27: Người quản lý đã đăng nhập | D27: N/A | E27: Quan sát góc trên trái danh sách | F27: Nút Thêm hiển thị màu xanh, đúng kích thước | G27: pass | H27: 17/09/2025 | I27: Vy
A28: QLX04 | B28: Kiểm tra nút Sửa hiển thị | C28: Có dữ liệu xe trong danh sách | D28: N/A | E28: Quan sát cột thao tác của xe | F28: Hiển thị nút Sửa màu xanh/đường dẫn chữ rõ ràng | G28: pass | H28: 17/09/2025 | I28: Vy
A29: QLX05 | B29: Kiểm tra nút Xóa hiển thị | C29: Có dữ liệu xe trong danh sách | D29: N/A | E29: Quan sát cột thao tác của xe | F29: Hiển thị nút Xóa màu đỏ/đường dẫn chữ rõ ràng | G29: pass | H29: 17/09/2025 | I29: Vy
A30: QLX06 | B30: Kiểm tra thanh Tìm kiếm | C30: Người quản lý đã đăng nhập | D30: N/A | E30: Quan sát phía trên bảng | F30: Có ô tìm kiếm hiển thị, placeholder đúng yêu cầu | G30: pass | H30: 17/09/2025 | I30: Vy
A31: QLX07 | B31: Kiểm tra dropdown hiển thị số bản ghi | C31: Người quản lý đã đăng nhập | D31: N/A | E31: Quan sát phía trên bảng | F31: Có dropdown chọn số bản ghi (10, 20, 50, …) | G31: pass | H31: 17/09/2025 | I31: Vy
A32: QLX08 | B32: Kiểm tra hiển thị popup khi nhấn Thêm | C32: Người quản lý đã đăng nhập | D32: N/A | E32: 1. Vào menu Quản lý xe 2. Nhấn nút Thêm | F32: Popup Thêm xe hiển thị đầy đủ | G32: pass | H32: 17/09/2025 | I32: Vy
A33: QLX09 | B33: Kiểm tra tiêu đề popup | C33: Popup Thêm đã mở | D33: N/A | E33: Quan sát popup | F33: Hiển thị tiêu đề “THÊM XE” đúng font, căn chỉnh chuẩn | G33: pass | H33: 17/09/2025 | I33: Vy
A34: QLX10 | B34: Kiểm tra các label trường nhập | C34: Popup Thêm đã mở | D34: N/A | E34: Quan sát form | F34: Các label hiển thị: Loại Xe, Biển số xe, Số Ghế, Tuyến đường, Trạng thái, Dịch vụ, Note | G34: pass | H34: 17/09/2025 | I34: Vy
A35: QLX11 | B35: Kiểm tra nút Thêm | C35: Popup Thêm đã mở | D35: N/A | E35: Quan sát cuối popup | F35: Hiển thị nút Thêm màu đỏ, căn trái | G35: pass | H35: 17/09/2025 | I35: Vy
A36: QLX12 | B36: Kiểm tra nút Đóng | C36: Popup Thêm đã mở | D36: N/A | E36: Quan sát cuối popup | F36: Hiển thị nút Đóng màu xanh, căn phải | G36: pass | H36: 17/09/2025 | I36: Vy
... A43: QLX19 | B43: Kiểm tra checkbox Dịch vụ | C43: Popup Sửa đã mở | D43: N/A | E43: Quan sát nhóm dịch vụ | F43: Hiển thị đầy đủ: Sạc điện thoại, Rèm cửa, Đưa/Đón khách tận nơi, Wifi, Khăn lạnh, Khác | G43: pass | H43: 17/09/2025 | I43: Vy
A44: GUI
A45: DANH SÁCH XE
A46: QLX20 | B46: Xác nhận hệ thống hiển thị đúng danh sách xe khi trong DB có dữ liệu | C46: Người quản lý nhà xe đã đăng nhập thành công; DB có ≥ 1 xe | D46: XeID=1, Loại=Limousine, Biển số=51A-12345, Số ghế=12, Tuyến=TP.HCM–Đà Lạt, Trạng thái=Đang hoạt động | E46: 1. Đăng nhập bằng tài khoản quản lý nhà xe 2. Click "Quản lý xe" | F46: Hệ thống hiển thị danh sách xe với đầy đủ thông tin (ID, Loại, Biển số, Số ghế, Tuyến, Trạng thái, Dịch vụ, Note) | G46: pass | H46: 17/09/2025 | I46: Vy
A47: QLX21 | B47: Xác nhận hệ thống hiển thị thông báo "Không có dữ liệu" khi DB không có xe | C47: Người quản lý nhà xe đã đăng nhập thành công; DB không có dữ liệu xe | D47: N/A | E47: 1. Đăng nhập bằng tài khoản quản lý nhà xe 2. Click "Quản lý xe" | F47: Hệ thống hiển thị thông báo “Không có dữ liệu” hoặc bảng rỗng | G47: pass | H47: 17/09/2025 | I47: Vy
A48: QLX22 | B48: Xác nhận hệ thống hiển thị kết quả chính xác khi tìm kiếm theo biển số hợp lệ | C48: Người quản lý nhà xe đã đăng nhập; DB có xe biển số "51A-12345" | D48: Biển số=51A-12345 | E48: 1. Đăng nhập bằng tài khoản quản lý nhà xe 2. Click "Quản lý xe" 3. Nhập “51A-12345” vào ô tìm kiếm 4. Nhấn "Tìm kiếm" | F48: Hệ thống hiển thị xe có biển số “51A-12345” | G48: pass | H48: 17/09/2025 | I48: Vy
A49: QLX23 | B49: Xác nhận hiển thị thông báo lỗi khi tìm kiếm theo biển số không tồn tại | C49: Người quản lý nhà xe đã đăng nhập; DB không có xe biển số “99X-99999” | D49: Biển số=99X-99999 | E49: 1. Đăng nhập bằng tài khoản quản lý nhà xe 2. Click "Quản lý xe" 3. Nhập “99X-99999” vào ô tìm kiếm 4. Nhấn "Tìm kiếm" | F49: Hệ thống hiển thị thông báo “Không tìm thấy dữ liệu” | G49: pass | H49: 17/09/2025 | I49: Vy
A50: QLX24 | B50: Xác nhận hệ thống hiển thị đúng dữ liệu khi danh sách xe có nhiều trang | C50: Người quản lý nhà xe đã đăng nhập; DB có > 20 xe | D50: 25 xe trong DB | E50: 1. Đăng nhập bằng tài khoản quản lý nhà xe 2. Click "Quản lý xe" 3. Chuyển sang trang 2 | F50: Hệ thống hiển thị đúng 10 xe tiếp theo; không bỏ sót/lặp dữ liệu | G50: pass | H50: 17/09/2025 | I50: Vy
A51: QLX25 | B51: Xác nhận hệ thống chuyển trang đúng khi click "Next" | C51: Người quản lý nhà xe đã đăng nhập; DB có > 20 xe | D51: 25 xe trong DB | E51: 1. Đăng nhập bằng tài khoản quản lý nhà xe 2. Click "Quản lý xe" 3. Nhấn nút "Next" | F51: Hệ thống chuyển sang trang 2 và hiển thị dữ liệu chính xác | G51: pass | H51: 17/09/2025 | I51: Vy
A52: QLX26 | B52: Xác nhận hệ thống quay lại trang trước khi click "Previous" | C52: Người quản lý nhà xe đã đăng nhập; DB có > 20 xe | D52: 25 xe trong DB | E52: 1. Đăng nhập bằng tài khoản quản lý nhà xe 2. Click "Quản lý xe" 3. Nhấn "Next" 4. Nhấn "Previous" | F52: Hệ thống quay lại trang đầu tiên, hiển thị dữ liệu chính xác | G52: pass | H52: 17/09/2025 | I52: Vy
A53: QLX27 | B53: Xác nhận mở popup Thêm xe khi click button “Thêm” | C53: Người quản lý nhà xe đã đăng nhập | D53: N/A | E53: 1. Đăng nhập bằng tài khoản quản lý nhà xe 2. Click "Quản lý xe" 3. Click nút “Thêm” | F53: Popup “Thêm xe” hiển thị | G53: pass | H53: 17/09/2025 | I53: Vy
A54: QLX28 | B54: Xác nhận popup Thêm xe không mở trùng lặp khi click nhiều lần | C54: Người quản lý nhà xe đã đăng nhập | D54: N/A | E54: 1. Đăng nhập bằng tài khoản quản lý nhà xe 2. Click "Quản lý xe" 3. Nhấn nút “Thêm” 2 lần | F54: Chỉ một popup “Thêm xe” hiển thị | G54: pass | H54: 17/09/2025 | I54: Vy
A55: QLX29 | B55: Xác nhận mở popup Sửa xe khi click button “Sửa” | C55: Người quản lý nhà xe đã đăng nhập | D55: N/A | E55: 1. Đăng nhập bằng tài khoản quản lý nhà xe 2. Click "Quản lý xe" 3. Click nút “Sửa” | F55: Popup “Sửa thông tin xe” hiển thị | G55: pass | H55: 17/09/2025 | I55: Vy
A56: QLX30 | B56: Xác nhận popup Sửa xe không mở trùng lặp khi click nhiều lần | C56: Người quản lý nhà xe đã đăng nhập | D56: N/A | E56: 1. Đăng nhập bằng tài khoản quản lý nhà xe 2. Click "Quản lý xe" 3. Nhấn nút “Sửa” 2 lần | F56: Chỉ một popup “Sửa thông tin xe” hiển thị | G56: pass | H56: 17/09/2025 | I56: Vy
A57: QLX31 | B57: Xác nhận mở popup Xóa xe khi click button “Xóa” | C57: Người quản lý nhà xe đã đăng nhập | D57: N/A | E57: 1. Đăng nhập bằng tài khoản quản lý nhà xe 2. Click "Quản lý xe" 3. Click nút “Xóa” | F57: Popup “Xóa thông tin xe” hiển thị | G57: pass | H57: 17/09/2025 | I57: Vy
A58: QLX32 | B58: Xác nhận popup Xóa xe không mở trùng lặp khi click nhiều lần | C58: Người quản lý nhà xe đã đăng nhập | D58: N/A | E58: 1. Đăng nhập bằng tài khoản quản lý nhà xe 2. Click "Quản lý xe" 3. Nhấn nút “Xóa” 2 lần | F58: Chỉ một popup “Xóa thông tin xe” hiển thị | G58: pass | H58: 17/09/2025 | I58: Vy
A59: POPUP THÊM THÔNG TIN XE
A60: QLX33 | B60: Xác nhận popup Thêm xe hiển thị đầy đủ các trường khi click “Thêm” | C60: Người quản lý nhà xe đã đăng nhập hợp lệ | D60: N/A | E60: 1. Đăng nhập bằng tài khoản quản lý nhà xe 2. Click "Quản lý xe". 3. Click nút Thêm. | F60: Popup “Thêm xe” hiển thị đầy đủ các mục: Loại xe (select), Biển số xe (input), Số ghế (input numeric), Tuyến đường (dropdown/search), Trạng thái (select: Đang hoạt động/Bảo trì/Ngưng hoạt động), Dịch vụ (checkbox list + Ô Khác), Note (textarea), nút Thêm (đỏ) và Đóng (xanh). | G60: pass | H60: 17/09/2025 | I60: Vy
A61: QLX34 | B61: Xác nhận không mở popup trùng lặp khi click “Thêm” nhiều lần | C61: Đã đăng nhập | D61: N/A | E61: 1. Đăng nhập bằng tài khoản quản lý nhà xe 2. Vào "Quản lý xe". 3. Nhấn nút Thêm 2–3 lần liên tiếp. | F61: Chỉ 1 popup hiển thị; các lần click sau không tạo popup mới hoặc bị ignore; focus ở popup hiện tại. | G61: pass | H61: 17/09/2025 | I61: Vy
A62: QLX35 | B62: Xác nhận giá trị mặc định của các trường khi mở popup | C62: Đã đăng nhập; danh sách tuyến có ít nhất 1 tuyến | D62: N/A | E62: 1. Đăng nhập bằng tài khoản quản lý nhà xe 2. Click "Quản lý xe". 3. Mở popup Thêm. | F62: Loại xe = (không chọn), Trạng thái = Đang hoạt động (mặc định), Dịch vụ = none, Note trống. | G62: pass | H62: 17/09/2025 | I62: Vy
A63: QLX36 | B63: Xác nhận hiển thị thông báo lỗi khi Loại xe bị để trống | C63: Đã đăng nhập; danh sách tuyến có ít nhất 1 tuyến | D63: Biển số=70B-55555; Số ghế=16; Tuyến=TP.HCM–Nha Trang | E63: 1. Đăng nhập bằng tài khoản quản lý nhà xe 2. Vào Quản lý xe. 3. Mở popup Thêm. 4. Để trống Loại xe; nhập Biển số=70B-55555, Số ghế=16, chọn Tuyến. 5. Click Thêm. | F63: Xác nhận hiển thị thông báo lỗi khi Loại xe để trống (vd: “Vui lòng chọn loại xe”). Không tạo bản ghi. Field Loại xe được highlight và focus. | G63: pass | H63: 17/09/2025 | I63: Vy
...

Sheet Quản lý chuyến đi
A1: Project Name | B1: XÂY DỰNG HỆ THÔNG QUẢN LÝ NHÀ XE TÍCH HỢP THANH TOÁN TRỰC TRUYẾN
A2: Module Code | B2: Quản lý chuyến đi
B3: Tổng số testcase | C3: Hoàn Thành | D3: Lỗi | E3: Bị chặn | F3: Tổng lần kiểm tra
A4: Round 1 | B4: =COUNTIF(A:A,"CD*") -> 121 | C4: =COUNTIF(G:G,"pass") -> 121 | D4: =COUNTIF(G:G,"failed") -> 0 | E4: =COUNTIF(G:G,"Block") -> 0
G23: Round 1
A24: Test Case ID | B24: Sumary | C24: Pre-condition | D24: Test Data | E24: Steps | F24: Expected Result | G24: Result | H24: Test Date | I24: Tester
A25: GUI
A26: QUẢN LÝ CHUYẾN ĐI
A27: CD01 | B27: Xác minh rằng tiêu đề "DANH SÁCH VÉ ĐÃ ĐẶT" hiển thị đúng | C27: Người dùng đã đăng nhập và truy cập module Quản lý chuyến đi | D27: N/A | E27: 1. Vào trang "Quản lý chuyến đi" | F27: Tiêu đề DANH SÁCH VÉ ĐÃ ĐẶT hiển thị rõ ràng, đúng font và căn chỉnh | G27: pass | H27: 17/09/2025 | I27: Vy
A28: CD02 | B28: Xác minh rằng các cột trong bảng hiển thị đầy đủ | C28: Người dùng đang ở trang Quản lý chuyến đi | D28: N/A | E28: 1. Quan sát bảng danh sách | F28: Các cột: Mã chuyến, Tên người lái, Phụ xe, ID xe, Tuyến đường, Số lượng khách hàng, Chi tiết hiển thị đầy đủ | G28: pass | H28: 17/09/2025 | I28: Vy
A29: CD03 | B29: Xác minh rằng các hàng dữ liệu được căn chỉnh hợp lý | C29: Có ít nhất 1 chuyến đã được tạo trong hệ thống | D29: N/A | E29: 1. Quan sát một dòng dữ liệu | F29: Dữ liệu trong mỗi ô hiển thị đúng, căn giữa/dọc, không bị lệch | G29: pass | H29: 17/09/2025 | I29: Vy
A30: CD04 | B30: Xác minh rằng nút Xem hiển thị trong cột Chi tiết | C30: Có chuyến đi đã được lưu trong hệ thống | D30: N/A | E30: 1. Quan sát cột “Chi tiết” | F30: Nút Xem hiển thị rõ ràng, màu xanh, dễ click | G30: pass | H30: 17/09/2025 | I30: Vy
A31: CD05 | B31: Xác minh rằng thanh tìm kiếm hiển thị đầy đủ | C31: Người dùng đang ở trang Quản lý chuyến đi | D31: N/A | E31: 1. Quan sát thanh tìm kiếm | F31: Ô tìm kiếm có placeholder “Nhập từ khóa…”, nút search hiển thị biểu tượng kính lúp | G31: pass | H31: 17/09/2025 | I31: Vy
A32: CD06 | B32: Xác minh rằng nút Sort hiển thị | C32: Người dùng đang ở trang Quản lý chuyến đi | D32: N/A | E32: 1. Quan sát góc phải trên bảng | F32: Nút Sort hiển thị với biểu tượng mũi tên sắp xếp | G32: pass | H32: 17/09/2025 | I32: Vy
A33: CD07 | B33: Xác minh rằng thanh phân trang hiển thị đúng | C33: Hệ thống có > 10 chuyến để phân trang | D33: N/A | E33: 1. Quan sát cuối bảng | F33: Thanh phân trang hiển thị các nút: Previous, số trang, Next với style rõ ràng | G33: pass | H33: 17/09/2025 | I33: Vy
A34: POPUP THÊM CHUYẾN ĐI
A35: CD08 | B35: Xác minh rằng tiêu đề popup “Thêm chuyến đi” hiển thị đúng | C35: Người dùng click nút “Thêm chuyến đi” | D35: N/A | E35: 1. Click “Thêm chuyến đi” | F35: Tiêu đề hiển thị: “Thêm chuyến đi”, font in đậm, căn giữa | G35: pass | H35: 17/09/2025 | I35: Vy
A36: CD09 | B36: Xác minh rằng các trường input hiển thị đầy đủ | C36: Người dùng mở popup Thêm chuyến đi | D36: N/A | E36: 1. Quan sát form | F36: Các trường: Mã chuyến, Xe, Tài xế, Phụ xe, Điểm đón, Điểm trả, Ngày/giờ, Thời lượng, Giá vé, Hình ảnh → hiển thị đủ | G36: pass | H36: 17/09/2025 | I36: Vy
A37: CD10 | B37: Xác minh rằng nút “Lưu” và “Hủy” hiển thị đúng | C37: Người dùng mở popup Thêm chuyến đi | D37: N/A | E37: 1. Quan sát cuối form | F37: Có nút Lưu (màu xanh) và Hủy (màu xám) hiển thị rõ ràng | G37: pass | H37: 17/09/2025 | I37: Vy
A38: CD11 | B38: Xác minh rằng form hiển thị đúng kích thước và căn giữa màn hình | C38: Người dùng mở popup Thêm chuyến đi | D38: N/A | E38: 1. Quan sát popup | F38: Popup hiển thị giữa màn hình, kích thước vừa khung, không tràn | G38: pass | H38: 17/09/2025 | I38: Vy
A39: POPUP SỬA THÔNG TIN CHUYẾN ĐI
A40: CD12 | B40: Xác minh rằng tiêu đề popup “Sửa chuyến đi” hiển thị đúng | C40: Người dùng click “Sửa” tại 1 chuyến có sẵn | D40: N/A | E40: 1. Click nút Sửa | F40: Tiêu đề hiển thị: “Sửa chuyến đi” rõ ràng | G40: pass | H40: 17/09/2025 | I40: Vy
A41: CD13 | B41: Xác minh rằng dữ liệu cũ được load lên form | C41: Người dùng mở popup Sửa chuyến đi | D41: Mã chuyến = CX001 | E41: 1. Mở popup Sửa 2. Quan sát form | F41: Các trường hiển thị sẵn thông tin của chuyến đi CX001 | G41: pass | H41: 17/09/2025 | I41: Vy
A42: CD14 | B42: Xác minh rằng trường Mã chuyến bị khóa (readonly) | C42: Người dùng mở popup Sửa chuyến đi | D42: CX001 | E42: 1. Mở popup Sửa 2. Quan sát trường Mã chuyến | F42: Trường Mã chuyến bị disable, không cho chỉnh sửa | G42: pass | H42: 17/09/2025 | I42: Vy
A43: CD15 | B43: Xác minh rằng có nút “Cập nhật” và “Hủy” hiển thị đúng | C43: Người dùng mở popup Sửa chuyến đi | D43: N/A | E43: 1. Quan sát cuối form | F43: Có nút Cập nhật (màu xanh) và Hủy (màu xám) | G43: pass | H43: 17/09/2025 | I43: Vy
A44: POPUP XÓA CHUYẾN ĐI
A45: CD16 | B45: Xác minh rằng tiêu đề popup “Xóa chuyến đi” hiển thị đúng | C45: Người dùng click nút “Xóa” tại 1 chuyến đi | D45: N/A | E45: 1. Click Xóa | F45: Tiêu đề hiển thị: “Xóa chuyến đi” | G45: pass | H45: 17/09/2025 | I45: Vy
A46: CD17 | B46: Xác minh rằng popup hiển thị nội dung cảnh báo rõ ràng | C46: Người dùng mở popup Xóa | D46: N/A | E46: 1. Mở popup 2. Quan sát text | F46: Hiển thị: “Bạn có chắc chắn muốn xóa chuyến đi này?” | G46: pass | H46: 17/09/2025 | I46: Vy
A47: CD18 | B47: Xác minh rằng có nút “Đồng ý” và “Hủy” hiển thị đúng | C47: Người dùng mở popup Xóa | D47: N/A | E47: 1. Quan sát dưới popup | F47: Có nút Đồng ý (màu đỏ) và Hủy (màu xám) hiển thị rõ | G47: pass | H47: 17/09/2025 | I47: Vy
A48: CD19 | B48: Xác minh rằng popup căn giữa màn hình | C48: Người dùng mở popup Xóa | D48: N/A | E48: 1. Mở popup 2. Quan sát | F48: Popup hiển thị giữa màn hình, kích thước vừa khung | G48: pass | H48: 17/09/2025 | I48: Vy
A49: CHI TIẾT CHUYẾN ĐI
A50: CD20 | B50: Xác minh rằng breadcrumb hiển thị đúng | C50: Người dùng click Xem ở màn Quản lý chuyến đi | D50: N/A | E50: 1. Vào trang "Chi tiết chuyến đi" | F50: Breadcrumb hiển thị: Chuyến đi > Chi tiết | G50: pass | H50: 17/09/2025 | I50: Vy
A51: CD21 | B51: Xác minh rằng mã vé hiển thị nổi bật | C51: Người dùng đã vào chi tiết một chuyến đi | D51: N/A | E51: 1. Quan sát phần mã vé | F51: Mã vé (VD: DL001) hiển thị màu xanh, có gạch dưới | G51: pass | H51: 17/09/2025 | I51: Vy
A52: CD22 | B52: Xác minh rằng bảng danh sách khách hàng hiển thị đầy đủ cột | C52: Chuyến đi có ít nhất 1 khách hàng đã đặt vé | D52: N/A | E52: 1. Quan sát bảng khách hàng | F52: Các cột: ID KH, Tên KH, SĐT, Mã Vé, Trạng Thái, Thao tác hiển thị đầy đủ | G52: pass | H52: 17/09/2025 | I52: Vy
A53: CD23 | B53: Xác minh rằng trạng thái thanh toán hiển thị đúng màu | C53: Có khách hàng ở cả 2 trạng thái thanh toán | D53: N/A | E53: 1. Quan sát cột trạng thái | F53: Trạng thái: Đã thanh toán hiển thị màu xanh, Chưa thanh toán hiển thị màu đỏ | G53: pass | H53: 17/09/2025 | I53: Vy
A54: CD24 | B54: Xác minh rằng cột thao tác có link Xem | C54: Có khách hàng trong danh sách | D54: N/A | E54: 1. Quan sát cột Thao tác | F54: Link Xem hiển thị màu xanh, có thể click | G54: pass | H54: 17/09/2025 | I54: Vy
A55: CD25 | B55: Xác minh rằng thông tin chuyến đi hiển thị rõ ràng | C55: Người dùng đã vào chi tiết một chuyến đi có đầy đủ thông tin | D55: N/A | E55: 1. Quan sát khung thông tin | F55: Hiển thị: địa điểm, loại xe, số ghế, giờ đi/đến, hình ảnh minh họa | G55: pass | H55: 17/09/2025 | I55: Vy
A56: CD26 | B56: Xác minh rằng phần giá vé và tổng thanh toán hiển thị chính xác | C56: Hệ thống đã lưu giá vé và tổng thanh toán cho chuyến đi | D56: N/A | E56: 1. Quan sát cuối trang | F56: Hiển thị: Giá vé, Giảm giá, Tổng thanh toán (màu đỏ, đậm) | G56: pass | H56: 17/09/2025 | I56: Vy
A57: CD27 | B57: Xác minh rằng nút In hiển thị | C57: Người dùng đã vào trang chi tiết chuyến đi | D57: N/A | E57: 1. Quan sát góc phải trên | F57: Nút In hiển thị màu đỏ với biểu tượng máy in | G57: pass | H57: 17/09/2025 | I57: Vy
A58: CHI TIẾT KHÁCH HÀNG
...
